Traceback (most recent call last):
  File "D:\Softwares\Anaconda\envs\jb\lib\site-packages\jupyter_cache\executors\utils.py", line 56, in single_nb_execution
    record_timing=False,
  File "D:\Softwares\Anaconda\envs\jb\lib\site-packages\nbclient\client.py", line 1204, in execute
    return NotebookClient(nb=nb, resources=resources, km=km, **kwargs).execute()
  File "D:\Softwares\Anaconda\envs\jb\lib\site-packages\nbclient\util.py", line 84, in wrapped
    return just_run(coro(*args, **kwargs))
  File "D:\Softwares\Anaconda\envs\jb\lib\site-packages\nbclient\util.py", line 62, in just_run
    return loop.run_until_complete(coro)
  File "D:\Softwares\Anaconda\envs\jb\lib\asyncio\base_events.py", line 587, in run_until_complete
    return future.result()
  File "D:\Softwares\Anaconda\envs\jb\lib\site-packages\nbclient\client.py", line 664, in async_execute
    cell, index, execution_count=self.code_cells_executed + 1
  File "D:\Softwares\Anaconda\envs\jb\lib\site-packages\nbclient\client.py", line 965, in async_execute_cell
    await self._check_raise_for_error(cell, cell_index, exec_reply)
  File "D:\Softwares\Anaconda\envs\jb\lib\site-packages\nbclient\client.py", line 862, in _check_raise_for_error
    raise CellExecutionError.from_cell_and_msg(cell, exec_reply_content)
nbclient.exceptions.CellExecutionError: An error occurred while executing the following cell:
------------------
# Load data
eqn = pd.read_csv("https://raw.githubusercontent.com/DL4CV-NPTEL/Deep-Learning-For-Computer-Vision/main/Data/Week%203/2nd_order.csv").to_numpy()
eqn = eqn[eqn[:, 0].argsort()]
x_2nd = eqn[:,0]
y_2nd = eqn[:,1]
np.set_printoptions(precision = 6)

# Find RANSAC model
ransac_2nd = Regression(2)
beta_2nd,error_2nd = ransac_2nd.solve(x_2nd, y_2nd, 2)
y_ransac_2nd = ransac_2nd.predict(x_2nd)

# Plot figures
ransac_2nd.visualize(x_2nd,y_2nd,y_ransac_2nd)

print("The coefficients are: ", beta_2nd)
print("The least square error is: {0:.6f}".format(error_2nd))
------------------

[1;31m---------------------------------------------------------------------------[0m
[1;31mNameError[0m                                 Traceback (most recent call last)
[1;32m<ipython-input-4-eb38eb85c35b>[0m in [0;36m<module>[1;34m[0m
[0;32m      7[0m [1;33m[0m[0m
[0;32m      8[0m [1;31m# Find RANSAC model[0m[1;33m[0m[1;33m[0m[1;33m[0m[0m
[1;32m----> 9[1;33m [0mransac_2nd[0m [1;33m=[0m [0mRegression[0m[1;33m([0m[1;36m2[0m[1;33m)[0m[1;33m[0m[1;33m[0m[0m
[0m[0;32m     10[0m [0mbeta_2nd[0m[1;33m,[0m[0merror_2nd[0m [1;33m=[0m [0mransac_2nd[0m[1;33m.[0m[0msolve[0m[1;33m([0m[0mx_2nd[0m[1;33m,[0m [0my_2nd[0m[1;33m,[0m [1;36m2[0m[1;33m)[0m[1;33m[0m[1;33m[0m[0m
[0;32m     11[0m [0my_ransac_2nd[0m [1;33m=[0m [0mransac_2nd[0m[1;33m.[0m[0mpredict[0m[1;33m([0m[0mx_2nd[0m[1;33m)[0m[1;33m[0m[1;33m[0m[0m

[1;31mNameError[0m: name 'Regression' is not defined
NameError: name 'Regression' is not defined

